{"name": "test_login_fail_invalid_data_user[case3]", "status": "passed", "parameters": [{"name": "case", "value": "{'user': '', 'passwd': '123456', 'check': '手机号不能为空'}"}], "start": 1646644851122, "stop": 1646644855925, "uuid": "24129f77-7d29-4ce3-83a0-dc382081d0fb", "historyId": "5a88e074aedae7759888bff0050d831c", "testCaseId": "10c4d51ec017e7c5efc5b856eeff46b2", "fullName": "TestCases.test_login.TestLogin#test_login_fail_invalid_data_user", "labels": [{"name": "feature", "value": "企业版登录页面-测试用户登录功能"}, {"name": "story", "value": "登录功能-用户名下方错误提示用例"}, {"name": "tag", "value": "@pytest.mark.usefixtures('testlogin_back')"}, {"name": "tag", "value": "run(order=1)"}, {"name": "parentSuite", "value": "TestCases"}, {"name": "suite", "value": "test_login"}, {"name": "subSuite", "value": "TestLogin"}, {"name": "host", "value": "2144-20210708JN"}, {"name": "thread", "value": "209740-MainThread"}, {"name": "framework", "value": "pytest"}, {"name": "language", "value": "cpython3"}, {"name": "package", "value": "TestCases.test_login"}]}